<?xml version="1.0" encoding="utf-8"?>
<!-- This URDF was automatically created by SolidWorks to URDF Exporter! Originally created by Stephen Brawner (brawner@gmail.com) 
     Commit Version: 1.5.1-0-g916b5db  Build Version: 1.5.7152.31018
     For more information, please see http://wiki.ros.org/sw_urdf_exporter -->
<robot
  name="planar_structure">

  <link name = "world" />

  <joint name="world_to_base_joint" type="fixed">
    <origin xyz="0 0 0.2" rpy="0 0 -1.5708"/>
    <parent link="world"/>
    <child link="lateral_link"/>
  </joint>

  <link
    name="lateral_link">
    <inertial>
      <origin
        xyz="0 0 0"
        rpy="0 0 0" />
      <mass
        value="1000" />
      <inertia
        ixx="800.066667"
        ixy="0"
        ixz="0"
        iyy="800.367"
        iyz="0"
        izz="800.367" />
    </inertial>
    <visual>
      <origin
        xyz="0 0 0"
        rpy="0 0 0" />
      <geometry>
        <mesh
          filename="package://planar_structure/meshes/base_link.STL" />
      </geometry>
      <material
        name="">
        <color
          rgba="0.79216 0.81961 0.93333 1" />
      </material>
    </visual>
    <collision>
      <origin
        xyz="0 0 0"
        rpy="0 0 0" />
      <geometry>
        <mesh
          filename="package://planar_structure/meshes/base_link.STL" />
      </geometry>
    </collision>
  </link>

  <joint
    name="lateral_joint"
    type="prismatic">
    <origin
      xyz="-1.2 0 0"
      rpy="1.5708 0 1.5708" />
    <parent
      link="lateral_link" />
    <child
      link="vertical_link" />
    <axis
      xyz="0 0 1" />
    <limit
      lower="-3.8"
      upper="3"
      effort="1000"
      velocity="10" />
    <dynamics
      damping="0.0"
      friction="0.1" />
  </joint>

  <link
    name="vertical_link">
    <inertial>
      <origin
        xyz="0 0 0"
        rpy="0 0 0" />
      <mass
        value="1.5" />
      <inertia
        ixx="2.215"
        ixy="0"
        ixz="0"
        iyy="0.7928"
        iyz="0"
        izz="2.215" />
    </inertial>
    <visual>
      <origin
        xyz="0 0 0"
        rpy="0 0 0" />
      <geometry>
        <mesh
          filename="package://planar_structure/meshes/vertical_link.STL" />
      </geometry>
      <material
        name="">
        <color
          rgba="0.79216 0.81961 0.93333 1" />
      </material>
    </visual>
    <collision>
      <origin
        xyz="0 0 0"
        rpy="0 0 0" />
      <geometry>
        <mesh
          filename="package://planar_structure/meshes/vertical_link.STL" />
      </geometry>
    </collision>
  </link>

  <joint
    name="vertical_joint"
    type="prismatic">
    <origin
      xyz="0 0.11 0.0"
      rpy="3.1416 -1.5708 0" />
    <parent
      link="vertical_link" />
    <child
      link="roll_link" />
    <axis
      xyz="0 -1 0" />
    <limit
      lower="0.01"
      upper="3.85"
      effort="1000"
      velocity="100" />
    <dynamics
      damping="0.0"
      friction="0.0" />
  </joint>

  <link
    name="roll_link">
    <inertial>
      <origin
        xyz="0 0 0"
        rpy="0 0 0" />
      <mass
        value="0.02" />
      <inertia
        ixx="0.5092"
        ixy="0"
        ixz="0"
        iyy="0.0081448"
        iyz="0"
        izz="0.5068" />
    </inertial>
    <visual>
      <origin
        xyz="0 0 0"
        rpy="0 0 0" />
      <geometry>
        <mesh
          filename="package://planar_structure/meshes/roll_link.STL" />
      </geometry>
      <material
        name="">
        <color
          rgba="0.79216 0.81961 0.93333 1" />
      </material>
    </visual>
    <collision>
      <origin
        xyz="0 0 0"
        rpy="0 0 0" />
      <geometry>
        <mesh
          filename="package://planar_structure/meshes/roll_link.STL" />
      </geometry>
    </collision>
  </link>

  <joint
    name="roll_joint"
    type="continuous">
    <origin
      xyz="0 0 0.45"
      rpy="0 -1.5708 1.5708" />
    <parent
      link="roll_link" />
    <child
      link="haptic_drone_with_structure/base_link" />
    <axis
      xyz="1 0 0" />
  </joint>
<!--
  <link
    name="cage">
    <inertial>
      <origin
        xyz="0 0 0"
        rpy="0 0 0" />
      <mass
        value="0.015" />
      <inertia
        ixx="0.00087148"
        ixy="1.2654E-05"
        ixz="5.3411E-06"
        iyy="0.00089445"
        iyz="5.3032E-06"
        izz="0.00093854" />
    </inertial>
    <visual>
      <origin
        xyz="0 0 0"
        rpy="1.5707963267949 0 0" />
      <geometry>
        <mesh
          filename="package://planar_structure/meshes/Cage.STL" />
      </geometry>
      <material
        name="">
        <color
          rgba="0.79216 0.81961 0.93333 1" />
      </material>
    </visual>
    <collision>
      <origin
        xyz="0 0 0"
        rpy="1.5707963267949 0 0" />
      <geometry>
        <mesh
          filename="package://planar_structure/meshes/Cage.STL" />
      </geometry>
    </collision>
  </link>

  <joint
    name="cage_joint"
    type="fixed">
    <origin
      xyz="0 0 0"
      rpy="0 0 1.5708" />
    <parent
      link="FT_sensor_nano17_measure" />
    <child
      link="cage" />
    <axis
      xyz="1 0 0" />
  </joint> -->

</robot>
